Workbook

Sheet losa horm
A1: Datos Arq | E1: Losa
A2: L1 | B2: 3.96 | C2: m | E2: Lmax | F2: =+MAX(B2:B5) -> 6.75 | G2: m | M2: Nervio | P2: Nervio | S2: Nervio
A3: L2 | B3: 6.75 | C3: m | E3: Viga int | F3: 1 | G3: u | M3: L | N3: =+B2 -> 3.96 | O3: m | P3: L | Q3: =+B3 -> 6.75 | R3: m | S3: L | T3: =+B4 -> 4.56 | U3: m
A4: L3 | B4: 4.56 | C4: m | E4: L real | F4: =+F2/(F3+1) -> 3.375 | G4: m | M4: at | N4: 0.5 | O4: m | P4: at | Q4: =+N4 -> 0.5 | R4: m | S4: at | T4: =+Q4 -> 0.5 | U4: m
A5: L4 | B5: 4.2 | C5: m | E5: hmin | F5: =+F4*100*0.03 -> 10.125 | G5: cm | M5: Cu | N5: =+'VIGAS horm'!B13 -> 1.16336 | O5: t/m2 | P5: Cu | Q5: =+N5 -> 1.16336 | R5: t/m2 | S5: Cu | T5: =+Q5 -> 1.16336 | U5: t/m2
A6: Pisos | B6: 2 | C6: u | E6: Imin | F6: =+F15*F5^3 /12 -> 8649.7559 | G6: cm4 | M6: Wr | N6: =+N5*N4 -> 0.58168 | O6: t/m | P6: Wr | Q6: =+Q5*Q4 -> 0.58168 | R6: t/m | S6: Wr | T6: =+T5*T4 -> 0.58168 | U6: t/m
A7: He | B7: 3.4 | C7: m | E7: I losa | F7: =+K28 -> 49097.222 | G7: cm4 | M7: Mu | N7: =+N6*N3^2 /12 -> 0.76013942 | O7: t-m | P7: Mu | Q7: =+Q6*Q3^2 /12 -> 2.2085663 | R7: t-m | S7: Mu | T7: =+T6*T3^2 /12 -> 1.0079351 | U7: t-m
E8: =+IF(F7<F6,"Suba h o Viga Intermedia","OK") -> OK | M8: b | N8: 10 | O8: cm | P8: b | Q8: 10 | R8: cm | S8: b | T8: 10 | U8: cm
A9: Paredes | B9: Pesado | M9: h | N9: =+F11 -> 25 | O9: cm | P9: h | Q9: =+N9 -> 25 | R9: cm | S9: h | T9: =+Q9 -> 25 | U9: cm
A10: Alivian | B10: Pesado | E10: Datos losa | M10: As | N10: =30*N7/(N9-3)*0.75 -> 0.77741532 | O10: cm2 | P10: As | Q10: =30*Q7/(Q9-3)*0.75 -> 2.2587609 | R10: cm2 | S10: As | T10: =30*T7/(T9-3)*0.75 -> 1.0308427 | U10: cm2
E11: Hl | F11: 25 | G11: cm | I11: V total | J11: =+F15*F15/10000*F11/100 -> 0.25 | K11: m3 | M11: As inf | N11: =+N10*0.65 -> 0.50531996 | O11: cm2 | P11: As inf | Q11: =+Q10*0.65 -> 1.4681946 | R11: cm2 | S11: As inf | T11: =+T10*0.65 -> 0.67004777 | U11: cm2
A12: Cm | B12: =+J16+0.08+B18+B19 -> 0.7028 | C12: t/m2 | E12: bn | F12: 10 | G12: cm | I12: V bloq | J12: =+F13^2*(F11-F14)*4/1000000 -> 0.128 | K12: m3
E13: bb | F13: 40 | G13: cm | I13: V horm | J13: =+J11-J12 -> 0.122 | K13: m3
E14: tc | F14: 5 | G14: cm | I14: Peso | J14: =+J13*2.4 -> 0.2928 | K14: t
E15: L total | F15: =2*F12+2*F13 -> 100 | G15: cm | I15: Area | J15: =+F15*F15/10000 -> 1 | K15: m2
E16: cg | F16: =+H28/F28 -> 16.944444 | G16: cm | I16: P horm | J16: =+J14/J15 -> 0.2928 | K16: t/m2
E17: h equival | F17: =+(12*F7/F15)^(0.333333333333333) -> 18.061177 | G17: cm
A18: Paredes | B18: =+IF(B9="Pesado",0.18,0.06) -> 0.18 | C18: t/m2 | E18: L max | F18: =+F17/0.03 /100 -> 6.0203924 | G18: m
A19: Alivian | B19: =+IF(B10="Pesado",0.75*(F11-F14)/100,0) -> 0.15 | C19: t/m2
E20: Plosa eq | F20: =2.4*F17/100 -> 0.43346826 | G20: t/m2
E21: P etabs | F21: =+B12-F20 -> 0.26933174 | G21: t/m2
F24: A | G24: y | H24: Ay | I24: Io | J24: d2 | K24: It
E25: 1 | F25: =+F12*(F11-F14) -> 200 | G25: =+(F11-F14)/2 -> 10 | H25: =+F25*G25 -> 2000 | I25: =+F12*(F11-F14)^3 /12 -> 6666.6667 | J25: =+(G25-$F$16)^2 -> 48.225309 | K25: =+I25+F25*J25 -> 16311.728
E26: 2 | F26: =+F25 -> 200 | G26: =+G25 -> 10 | H26: =+F26*G26 -> 2000 | I26: =+I25 -> 6666.6667 | J26: =+(G26-$F$16)^2 -> 48.225309 | K26: =+I26+F26*J26 -> 16311.728
E27: 3 | F27: =+F15*F14 -> 500 | G27: =+F11-F14/2 -> 22.5 | H27: =+F27*G27 -> 11250 | I27: =+F15*F14^3 /12 -> 1041.6667 | J27: =+(G27-$F$16)^2 -> 30.864198 | K27: =+I27+F27*J27 -> 16473.765
F28: =SUM(F25:F27) -> 900 | H28: =SUM(H25:H27) -> 15250 | K28: =SUM(K25:K27) -> 49097.222

Sheet VIGAS horm
A1: Datos Arq | E1: Viga
A2: L1 | B2: =+'losa horm'!B2 -> 3.96 | C2: m | E2: Lv | F2: =+MAX(B2:B3) -> 6.75 | G2: m | I2: Cortante
A3: L2 | B3: =+'losa horm'!B3 -> 6.75 | C3: m | E3: Lt | F3: =+AVERAGE(B4:B5) -> 4.38 | G3: m | I3: Vug | J3: =+(2*F2-F3)*F3*B13/4 -> 11.617778 | K3: t
A4: L3 | B4: =+'losa horm'!B4 -> 4.56 | C4: m | E4: Mdis | F4: =+B13*F3*(F2-0.3)^2 /8 *0.65*0.85*1.1 -> 16.104329 | G4: t-m | I4: Vum | J4: =+(J18+J19)/(F2-J17-F11/25) -> 6.4833242 | K4: t
A5: L4 | B5: =+'losa horm'!B5 -> 4.2 | C5: m | E5: Mres | F5: =0.9*(F21*B17*(F13-F31/2))/100000 -> 14.772171 | G5: t-m | I5: Vu | J5: =SUM(J3:J4) -> 18.101103 | K5: t
A6: Pisos | B6: =+'losa horm'!B6 -> 2 | C6: u | E6: D/C | F6: =+F4/F5 -> 1.0901803 | I6: Vc | J6: =0.53*B16^0.5*F8*F13/1000 -> 6.61285 | K6: t
A7: He | B7: =+'losa horm'!B7 -> 3.4 | C7: m | E7: Datos viga | I7: Vs | J7: =+(J5-0.75*J6)/0.75 -> 17.521953 | K7: t
A8: Uso | B8: Vivienda | E8: b | F8: 30 | G8: cm | I8: fi | J8: 10 | K8: mm
E9: rec | F9: 2.5 | G9: cm | I9: Ab | J9: =0.00785*J8^2 -> 0.785 | K9: cm2
E10: hmin | F10: =+ROUNDUP((F4*100000/0.145/B16/F8)^0.5+F9,0) -> 45 | G10: cm | I10: s | J10: =+F13*J9*2*B17/J7/1000 -> 10.800611 | K10: cm
A11: =+'losa horm'!A12 -> Cm | B11: =+'losa horm'!B12 -> 0.7028 | C11: =+'losa horm'!C12 -> t/m2 | E11: hdef | F11: 33 | G11: cm | I11: smax | J11: =ROUNDUP(MIN(F13/4,6*F16/10,10,J10),0) -> 8 | K11: cm
A12: Cv | B12: =+IF(B8="Vivienda",0.2,IF(B8="Oficina",0.25,IF(B8="Pesada",0.48,0.35))) -> 0.2 | C12: t/m2 | E12: rel | F12: =+F11/F8 -> 1.1 | G12: =+IF(F12<1.1,"NO",IF(F12>1.6,"NO","OK")) -> OK | I12: Zprot | J12: =2*F11 -> 66 | K12: cm
A13: Cu | B13: =+B11*1.2+B12*1.6 -> 1.16336 | C13: t/m2 | E13: d | F13: =+F11-F9-J8/10-F16/20 -> 28.7 | G13: cm | I13: Z centrl | J13: =+(F2-J17-J12/50)*100 -> 513 | K13: cm
E14: d' | F14: =+F11-F13 -> 4.3 | G14: cm | I14: smax | J14: =+ROUNDUP(MIN(F13/2,8*F16/10,15),0) -> 13 | K14: cm
A15: Z sismica | C15: Alta | E15: Asmin | F15: =14*F8*F13/B17 -> 2.87 | G15: cm2
A16: fc | B16: 210 | C16: kg/cm2 | E16: fi | F16: 16 | G16: mm
A17: fy | B17: 4200 | C17: kg/cm2 | E17: Ab | F17: =0.00785*F16^2 -> 2.0096 | G17: cm2 | I17: bcol | J17: =+'COL horm'!F9/100 -> 0.3 | K17: m
E18: Num | F18: =MAX(INT(F15/F17),2) -> 2 | G18: u | I18: Mpr(-) | J18: =1.25*F21*B17*(F13-1.25*F21*B17/1.7/B16/F8)/100000 -> 18.833209 | K18: t-m
E19: As(-) | F19: =30*F4/F13 -> 16.833794 | G19: cm2 | I19: Mpr(+) | J19: =1.25*F29*B17*(F13-1.25*F29*B17/1.7/B16/F8)/100000 -> 14.426245 | K19: t-m
A20: pb | B20: =0.85*0.85*B16/B17*(6100/(6100+B17)) -> 0.021394417 | E20: Num | F20: =+INT((F19-F18*F17)/F17)+1 -> 7 | G20: u
A21: pmax | B21: =+IF(C15="Alta",0.5*B20,0.75*B20) -> 0.010697209 | E21: As total | F21: =+(F18+F20)*F17 -> 18.0864 | G21: cm2
E22: Cuant | F22: =+F21/F8/F11 -> 0.018269091 | G22: =+IF(F22<B21,"OK","NO") -> NO
E24: sep | F24: =+(F8-2*F9-2-(F18+F20)*F16/10)/(F18+F20-1) -> 1.075 | G24: =+IF(F24>MAX(F16/10,2.54),"OK","NO") -> NO
E25: As(+) | F25: =0.67*F21 -> 12.117888 | G25: cm2
E26: fi | F26: 16 | G26: mm
E27: Ab | F27: =0.00785*F26^2 -> 2.0096 | G27: cm2
E28: Num | F28: =+INT(F25/F27) -> 6 | G28: u
E29: As total | F29: =+F28*F27 -> 12.0576 | G29: cm2
E30: Cuant | F30: =+F29/F8/F11 -> 0.012179394 | G30: =+IF(F30>F22/2,"OK","NO") -> OK
E31: a | F31: =+F21*B17/0.85/B16/F8 -> 14.185412 | G31: cm
E32: Lmax vol | F32: =+(2*F5/B13)^0.33333 -> 2.9393325 | G32: m

Sheet Hoja2

Sheet COL horm
A1: Datos Arq | E1: Calculos
A2: L1 | B2: =+'losa horm'!B2 -> 3.96 | C2: m | E2: At | F2: =+(B2/2+B3/2)*(B4/2+B5/2) -> 23.4549 | G2: m2 | I2: Num var | J2: =+F10*2+(F11-2)*2 -> 8 | K2: u | O2: M | P2: P
A3: L2 | B3: =+'losa horm'!B3 -> 6.75 | C3: m | E3: fm | F3: 1.3 | I3: As | J3: =4*0.00785*F12^2+(J2-4)*0.00785*F13^2 -> 9.0432 | K3: cm2 | N3: 1 | O3: 0 | P3: =+(0.85*B14*(F6-J3)+J3*B15)/1000 -> 197.01723 | Q3: =+P3*0.8 -> 157.61378
A4: L3 | B4: =+'losa horm'!B4 -> 4.56 | C4: m | E4: Pult | F4: =+F2*B12*B6*F3/0.85 -> 83.464565 | G4: t | I4: ac | J4: =+F8-2*F17-F14/10 -> 24 | K4: cm | N4: 2 | O4: =+((2*0.00785*F12^2*B15*(F9/2-O8)+(F10-2)*0.00785*F13^2*B15*(F9/2-O8))*2+0.85*B14*F8*O9*(F9/2-O9/2))/100000 -> 9.1215501 | P4: =+P3/3 -> 65.67241
A5: L4 | B5: =+'losa horm'!B5 -> 4.2 | C5: m | E5: Ag nec | F5: =3*F4*1000/(0.85*B14+0.012*B15) -> 1093.8999 | G5: cm2 | I5: pc | J5: =+F9-2*F17-F14/10 -> 24 | K5: cm | N5: 3 | O5: 0 | P5: =+J3*B15/1000*-1 -> -37.98144
A6: Pisos | B6: =+'losa horm'!B6 -> 2 | C6: u | E6: Ag nec | F6: =+F8*F9 -> 900 | G6: cm2 | I6: Ac | J6: =+J4*J5 -> 576 | K6: cm2
A7: He | B7: =+'losa horm'!B7 -> 3.4 | C7: m | E7: Datos de col | N7: d | O7: =+F9-F17-F14/10-F12/20 -> 25.9 | P7: cm
E8: ancho | F8: 30 | G8: cm | I8: Chequeos | N8: d' | O8: =+F9-O7 -> 4.1 | P8: cm
E9: prof | F9: 30 | G9: cm | I9: Cuant | J9: =+J3/F6 -> 0.010048 | K9: =+IF(J9>1%,"OK","NO") -> OK | N9: c | O9: =+O7*0.003/0.005 -> 15.54 | P9: cm
A10: =+'losa horm'!A12 -> Cm | B10: =+'losa horm'!B12 -> 0.7028 | C10: =+'losa horm'!C12 -> t/m2 | E10: var a | F10: 3 | G10: u | I10: sep a | J10: =+(J4-F14/10-2*F12/10-(F10-2)*F13/10)/(F10-1) -> 9.7 | K10: =+IF(J10<15,"OK","NO") -> OK
A11: Cv | B11: =+'VIGAS horm'!B12 -> 0.2 | C11: t/m2 | E11: var p | F11: 3 | G11: u | I11: sep b | J11: =+(J5-F14/10-2*F12/10-(F11-2)*F13/10)/(F11-1) -> 9.7 | K11: =+IF(J11<15,"OK","NO") -> OK | M11: INT | N11: 5.3
A12: Cu | B12: =+B10*1.2+B11*1.6 -> 1.16336 | C12: t/m2 | E12: fi esq | F12: 12 | G12: mm | I12: Confinamiento | M12: MED | N12: 4
E13: fi long | F13: 12 | G13: mm | I13: Ash | J13: =+MAX(0.3*J4*F15*B14/B15*(F6/J6-1),0.09*J4*F15*B14/B15) -> 1.62 | K13: cm2 | M13: ESQ | N13: 3.2
A14: fc | B14: =+'VIGAS horm'!B16 -> 210 | C14: kg/cm2 | E14: fi est | F14: 10 | G14: mm | I14: vinc | J14: =ROUNDUP(J13/0.00785/F14^2,0)-2 -> 1 | K14: u
A15: fy | B15: =+'VIGAS horm'!B17 -> 4200 | C15: kg/cm2 | E15: sep | F15: 8 | G15: =+IF(F15<=J15,"OK","NO") -> OK | I15: sep max | J15: =+ROUNDUP(MIN(6*F12/10,10),0) -> 8 | K15: cm | M15: NF - VD
E16: vinch | F16: 1 | G16: =+IF(F16>=J14,"OK","NO") -> OK | M16: T1 | N16: =+'VIGAS horm'!F21*B15*1.25/1000 -> 94.9536 | O16: t | P16: Condiciones
A17: Tipo col | B17: INT | E17: rec | F17: 2.5 | G17: cm | M17: T2 | N17: =+'VIGAS horm'!F29*B15*1.25/1000 -> 63.3024 | O17: t | Q17: Act | R17: Res
I18: CF - VD | M18: Vcol | N18: =+J20/B7 -> 9.7821922 | O18: t | P18: Vhz | Q18: =+N19 -> 148.47381 | R18: =+N20 -> 58.755287 | S18: =+IF(R18>Q18,"OK","NO") -> NO
I19: ∑Mcol | J19: =+O4*2 -> 18.2431 | K19: =+J19/J20 -> 0.54850872 | M19: Vj | N19: =+N16+N17-N18 -> 148.47381 | O19: t | P19: Vvt | Q19: =+'VIGAS horm'!F11 -> 33 | R19: =+F9 -> 30 | S19: =+IF(R19>=Q19,"OK","NO") -> NO
I20: ∑Mvig | J20: =+'VIGAS horm'!J18+'VIGAS horm'!J19 -> 33.259453 | M20: Vn | N20: =+N24*B14^0.5*N25*0.85/1000 -> 58.755287 | O20: t | P20: Adh | Q20: =20*'VIGAS horm'!F16/10 -> 32 | R20: =+F9 -> 30 | S20: =+IF(R20>=Q20,"OK","NO") -> NO
I21: =+IF(K19>1.2,"OK","NO") -> NO | P21: =+IF(S41=1,"OK","NO") -> NO
M22: a | N22: =+IF(B17=M11,N11,IF(B17=M12,N12,N13)) -> 5.3
M23: Cond | N23: =+IF(N26<0.75*F8,"Baje","Mantenga") -> Mantenga
M24: a def | N24: 5.3
M25: Ac | N25: =+(N26+F8)/2*F9 -> 900 | O25: cm2
M26: Bb | N26: =+'VIGAS horm'!F8 -> 30 | O26: cm
P28: var x | Q28: var y | R28: fi esq | S28: fi l | T28: fi est | U28: sep | V28: vinc
O29: C50 | P29: 5 | Q29: 5 | R29: 16 | S29: 14 | T29: 10 | U29: 10 | V29: 1
O30: C30X40 | P30: 4 | Q30: 3 | R30: 14 | S30: 12 | T30: 10 | U30: 9 | V30: 0
O31: C40X30 | V31: 1
S38: =+IF(S18="OK",1,0) -> 0
S39: =+IF(S19="OK",1,0) -> 0
S40: =+IF(S20="OK",1,0) -> 0
S41: =+S38*S39*S40 -> 0

Sheet VIGAS MET
A1: Datos Arq | E1: Viga Sec | U1: VIGAS PRINCIPALES
A2: L1 | B2: =+'losa horm'!B2 -> 3.96 | C2: m | E2: Cuad 1 | I2: Cuad 2 | M2: Cuad 3 | Q2: Cuad 4 | U2: Viga Izq | Y2: Viga der
A3: L2 | B3: =+'losa horm'!B3 -> 6.75 | C3: m | E3: A | F3: 36 | G3: ksi | I3: A | J3: =+F3 -> 36 | K3: ksi | M3: A | N3: =+J3 -> 36 | O3: ksi | Q3: A | R3: =+N3 -> 36 | S3: ksi | U3: A | V3: 36 | W3: ksi | Y3: A | Z3: =+V3 -> 36 | AA3: ksi
A4: L3 | B4: =+'losa horm'!B4 -> 4.56 | C4: m | E4: Lt | F4: =+B2 -> 3.96 | G4: m | I4: Lt | J4: =+B3 -> 6.75 | K4: m | M4: Lt | N4: =+F4 -> 3.96 | O4: m | Q4: Lt | R4: =+B3 -> 6.75 | S4: m | U4: Vp | V4: =+B2 -> 3.96 | W4: m | Y4: Vp | Z4: =+B3 -> 6.75 | AA4: m
A5: L4 | B5: =+'losa horm'!B5 -> 4.2 | C5: m | E5: Lv | F5: =+B4 -> 4.56 | G5: m | I5: Lv | J5: =+F5 -> 4.56 | K5: m | M5: Lv | N5: =+B5 -> 4.2 | O5: m | Q5: Lv | R5: =+B5 -> 4.2 | S5: m | U5: Num | V5: =+F6 -> 2 | W5: u | Y5: Num | Z5: =+J6 -> 4 | AA5: u
A6: Pisos | B6: =+'losa horm'!B6 -> 2 | C6: u | E6: Num | F6: 2 | G6: u | I6: Num | J6: 4 | K6: u | M6: Num | N6: =+F6 -> 2 | O6: u | Q6: Num | R6: =+J6 -> 4 | S6: u | U6: Pi | V6: =+F9/2+N9/2 -> 5.2147798 | W6: t | Y6: Pi | Z6: =+J9/2+R9/2 -> 5.3318441 | AA6: t
A7: He | B7: =+'losa horm'!B7 -> 3.4 | C7: m | E7: at | F7: =+F4/(F6+1) -> 1.32 | G7: m | I7: at | J7: =+J4/(J6+1) -> 1.35 | K7: m | M7: at | N7: =+N4/(N6+1) -> 1.32 | O7: m | Q7: at | R7: =+R4/(R6+1) -> 1.35 | S7: m | U7: Tipo | V7: EMP | Y7: Tipo | Z7: EMP
B8: =+'VIGAS horm'!B8 -> Vivienda | E8: =+IF(F7<1.2,"Antiecon",IF(F7>1.6,"Antiecon","OK")) -> OK | I8: =+IF(J7<1.2,"Antiecon",IF(J7>1.6,"Antiecon","OK")) -> OK | M8: =+IF(N7<1.2,"Antiecon",IF(N7>1.6,"Antiecon","OK")) -> OK | Q8: =+IF(R7<1.2,"Antiecon",IF(R7>1.6,"Antiecon","OK")) -> OK | U8: Mult | V8: =+IF(V7=U49,V49,V50) -> 4.5890062 | W8: t-m | Y8: Mult | Z8: =+IF(Z7=Y49,Z49,Z50) -> 14.395979 | AA8: t-m
E9: Wt | F9: =+F7*F5*$B$13+F23/1000*F5*1.2 -> 5.4290858 | G9: t | I9: Wt | J9: =+J7*J5*$B$13+J23/1000*J5*1.2 -> 5.550961 | K9: t | M9: Wt | N9: =+N7*N5*$B$13+N23/1000*N5*1.2 -> 5.0004738 | O9: t | Q9: Wt | R9: =+R7*R5*$B$13+R23/1000*R5*1.2 -> 5.1127272 | S9: t | U9: Mres | V9: =0.9*V24*V22/100000 -> 6.5222589 | W9: t-m | Y9: Mres | Z9: =0.9*Z24*Z22/100000 -> 16.698637 | AA9: t-m
E10: wr | F10: =+F9/F5 -> 1.190589 | G10: t/m | I10: wr | J10: =+J9/J5 -> 1.217316 | K10: t/m | M10: wr | N10: =+N9/N5 -> 1.190589 | O10: t/m | Q10: wr | R10: =+R9/R5 -> 1.217316 | S10: t/m | U10: D/C | V10: =+V8/V9 -> 0.70359155 | Y10: D/C | Z10: =+Z8/Z9 -> 0.86210505
A11: =+'losa horm'!A12 -> Cm | B11: =+'DATOS MEMORIA'!C25/1000 -> 0.47575 | C11: =+'losa horm'!C12 -> t/m2 | E11: Mult | F11: =+F10*F5^2 /8 -> 3.0945789 | G11: t-m | I11: Mult | J11: =+J10*J5^2 /8 -> 3.1640477 | K11: t-m | M11: Mult | N11: =+N10*N5^2 /8 -> 2.6252487 | O11: t-m | Q11: Mult | R11: =+R10*R5^2 /8 -> 2.6841818 | S11: t-m | U11: Apoyo lat | W11: =+IF(V25>F7*100,"OK","NO") -> OK | Y11: Apoyo lat | AA11: =+IF(Z25>J7*100,"OK","NO") -> OK
A12: Cv | B12: =+'VIGAS horm'!B12 -> 0.2 | C12: t/m2 | E12: Mres | F12: =0.9*F28*F26/100000 -> 3.3897048 | G12: t-m | I12: Mres | J12: =0.9*J28*J26/100000 -> 3.3897048 | K12: t-m | M12: Mres | N12: =0.9*N28*N26/100000 -> 3.3897048 | O12: t-m | Q12: Mres | R12: =0.9*R28*R26/100000 -> 3.3897048 | S12: t-m | U12: Cortante | W12: =+IF(V38>V37,"OK","Suba tw") -> OK | Y12: Cortante | AA12: =+IF(Z38>Z37,"OK","Suba tw") -> OK | AD12: sidec 9
A13: Cu | B13: =+B11*1.2+B12*1.6 -> 0.8909 | C13: t/m2 | E13: D/C | F13: =+F11/F12 -> 0.91293463 | I13: D/C | J13: =+J11/J12 -> 0.93342869 | M13: D/C | N13: =+N11/N12 -> 0.77447709 | Q13: D/C | R13: =+R11/R12 -> 0.79186298 | U13: Datos de viga | Y13: Datos de viga
E14: Apoyo | F14: 5 | G14: =+IF(F15<F29,"OK","NO") -> OK | I14: Apoyo | J14: 5 | K14: =+IF(J15<J29,"OK","NO") -> OK | M14: Apoyo | N14: 2 | O14: =+IF(N15<N29,"OK","NO") -> NO | Q14: Apoyo | R14: 2 | S14: =+IF(R15<R29,"OK","NO") -> NO | U14: bf | V14: 12 | W14: =+IF(V14/2/V15<V27,"SISM",IF(V14/2/V15<V28,"COMP","NCOMP")) -> SISM | Y14: bf | Z14: 16 | AA14: =+IF(Z14/2/Z15<Z27,"SISM",IF(Z14/2/Z15<Z28,"COMP","NCOMP")) -> SISM
E15: Lb | F15: =+F5*100/(F14+1) -> 76 | G15: cm | I15: Lb | J15: =+J5*100/(J14+1) -> 76 | K15: cm | M15: Lb | N15: =+N5*100/(N14+1) -> 140 | O15: cm | Q15: Lb | R15: =+R5*100/(R14+1) -> 140 | S15: cm | U15: tf | V15: 0.7 | W15: cm | Y15: tf | Z15: 1 | AA15: cm
U16: h | V16: 27 | W16: =+IF(V16/V17<V29,"SISM",IF(V16/V17<V30,"COMP","NCOMP")) -> SISM | Y16: h | Z16: 36 | AA16: =+IF(Z16/Z17<Z29,"SISM",IF(Z16/Z17<Z30,"COMP","NCOMP")) -> SISM
E17: Datos de viga | I17: Datos de viga | M17: Datos de viga | Q17: Datos de viga | U17: tw | V17: 0.4 | W17: cm | Y17: tw | Z17: 0.6 | AA17: cm
E18: bf | F18: 8 | G18: =+IF(F18/2/F19<F32,"SISM",IF(F18/2/F19<F33,"COMP","NCOMP")) -> SISM | I18: bf | J18: =+F18 -> 8 | K18: =+IF(J18/2/J19<J32,"SISM",IF(J18/2/J19<J33,"COMP","NCOMP")) -> SISM | M18: bf | N18: =+J18 -> 8 | O18: =+IF(N18/2/N19<N32,"SISM",IF(N18/2/N19<N33,"COMP","NCOMP")) -> SISM | Q18: bf | R18: =+N18 -> 8 | S18: =+IF(R18/2/R19<R32,"SISM",IF(R18/2/R19<R33,"COMP","NCOMP")) -> SISM | U18: As | V18: =+V14*V16-(V14-V17)*(V16-2*V15) -> 27.04 | W18: cm2 | Y18: As | Z18: =+Z14*Z16-(Z14-Z17)*(Z16-2*Z15) -> 52.4 | AA18: cm2
E19: tf | F19: 0.5 | G19: cm | I19: tf | J19: =+F19 -> 0.5 | K19: cm | M19: tf | N19: =+J19 -> 0.5 | O19: cm | Q19: tf | R19: =+N19 -> 0.5 | S19: cm | U19: Peso | V19: =+V18*0.785 -> 21.2264 | W19: kg/m | Y19: Peso | Z19: =+Z18*0.785 -> 41.134 | AA19: kg/m
E20: h | F20: 26 | G20: =+IF(F20/F21<F34,"SISM",IF(F20/F21<F35,"COMP","NCOMP")) -> COMP | I20: h | J20: 26 | K20: =+IF(J20/J21<J34,"SISM",IF(J20/J21<J35,"COMP","NCOMP")) -> COMP | M20: h | N20: 26 | O20: =+IF(N20/N21<N34,"SISM",IF(N20/N21<N35,"COMP","NCOMP")) -> COMP | Q20: h | R20: 26 | S20: =+IF(R20/R21<R34,"SISM",IF(R20/R21<R35,"COMP","NCOMP")) -> COMP | U20: Ix | V20: =+V14*V16^3 /12-(V14-V17)*(V16-2*V15)^3 /12 -> 3465.0245 | W20: cm4 | Y20: Ix | Z20: =+Z14*Z16^3 /12-(Z14-Z17)*(Z16-2*Z15)^3 /12 -> 11767.867 | AA20: cm4
E21: tw | F21: 0.3 | G21: cm | I21: tw | J21: =+F21 -> 0.3 | K21: cm | M21: tw | N21: =+J21 -> 0.3 | O21: cm | Q21: tw | R21: =+N21 -> 0.3 | S21: cm | U21: Iy | V21: =+V15*V14^3 /6+(V16-2*V15)*V17^3 /12 -> 201.73653 | W21: cm4 | Y21: Iy | Z21: =+Z15*Z14^3 /6+(Z16-2*Z15)*Z17^3 /12 -> 683.27867 | AA21: cm4
E22: As | F22: =+F18*F20-(F18-F21)*(F20-2*F19) -> 15.5 | G22: cm2 | I22: As | J22: =+J18*J20-(J18-J21)*(J20-2*J19) -> 15.5 | K22: cm2 | M22: As | N22: =+N18*N20-(N18-N21)*(N20-2*N19) -> 15.5 | O22: cm2 | Q22: As | R22: =+R18*R20-(R18-R21)*(R20-2*R19) -> 15.5 | S22: cm2 | U22: Zx | V22: =+V14*V15*(V16-V15)+(V16/2-V15)^2*V17 -> 286.456 | W22: cm3 | Y22: Zx | Z22: =+Z14*Z15*(Z16-Z15)+(Z16/2-Z15)^2*Z17 -> 733.4 | AA22: cm3
E23: Peso | F23: =+F22*0.785 -> 12.1675 | G23: kg/m | I23: Peso | J23: =+J22*0.785 -> 12.1675 | K23: kg/m | M23: Peso | N23: =+N22*0.785 -> 12.1675 | O23: kg/m | Q23: Peso | R23: =+R22*0.785 -> 12.1675 | S23: kg/m | U23: ry | V23: =+(V21/V18)^0.5 -> 2.7314228 | W23: cm | Y23: ry | Z23: =+(Z21/Z18)^0.5 -> 3.6110482 | AA23: cm
E24: Ix | F24: =+F18*F20^3 /12-(F18-F21)*(F20-2*F19)^3 /12 -> 1691.2917 | G24: cm4 | I24: Ix | J24: =+J18*J20^3 /12-(J18-J21)*(J20-2*J19)^3 /12 -> 1691.2917 | K24: cm4 | M24: Ix | N24: =+N18*N20^3 /12-(N18-N21)*(N20-2*N19)^3 /12 -> 1691.2917 | O24: cm4 | Q24: Ix | R24: =+R18*R20^3 /12-(R18-R21)*(R20-2*R19)^3 /12 -> 1691.2917 | S24: cm4 | U24: fy | V24: =V3*1000/14.23 -> 2529.8665 | W24: kg/cm2 | Y24: fy | Z24: =Z3*1000/14.23 -> 2529.8665 | AA24: kg/cm2
E25: Iy | F25: =+F19*F18^3 /6+(F20-2*F19)*F21^3 /12 -> 42.722917 | G25: cm4 | I25: Iy | J25: =+J19*J18^3 /6+(J20-2*J19)*J21^3 /12 -> 42.722917 | K25: cm4 | M25: Iy | N25: =+N19*N18^3 /6+(N20-2*N19)*N21^3 /12 -> 42.722917 | O25: cm4 | Q25: Iy | R25: =+R19*R18^3 /6+(R20-2*R19)*R21^3 /12 -> 42.722917 | S25: cm4 | U25: Lp | V25: =1.76*V23*V26 -> 138.50404 | W25: cm | Y25: Lp | Z25: =1.76*Z23*Z26 -> 183.10778 | AA25: cm
E26: Zx | F26: =+F18*F19*(F20-F19)+(F20/2-F19)^2*F21 -> 148.875 | G26: cm3 | I26: Zx | J26: =+J18*J19*(J20-J19)+(J20/2-J19)^2*J21 -> 148.875 | K26: cm3 | M26: Zx | N26: =+N18*N19*(N20-N19)+(N20/2-N19)^2*N21 -> 148.875 | O26: cm3 | Q26: Zx | R26: =+R18*R19*(R20-R19)+(R20/2-R19)^2*R21 -> 148.875 | S26: cm3 | U26: Cte | V26: =+(2100000/V24)^0.5 -> 28.811167 | Y26: Cte | Z26: =+(2100000/Z24)^0.5 -> 28.811167
E27: ry | F27: =+(F25/F22)^0.5 -> 1.660216 | G27: cm | I27: ry | J27: =+(J25/J22)^0.5 -> 1.660216 | K27: cm | M27: ry | N27: =+(N25/N22)^0.5 -> 1.660216 | O27: cm | Q27: ry | R27: =+(R25/R22)^0.5 -> 1.660216 | S27: cm | U27: cf1 | V27: =0.3*V26 -> 8.64335 | Y27: cf1 | Z27: =0.3*Z26 -> 8.64335
E28: fy | F28: =F3*1000/14.23 -> 2529.8665 | G28: kg/cm2 | I28: fy | J28: =J3*1000/14.23 -> 2529.8665 | K28: kg/cm2 | M28: fy | N28: =N3*1000/14.23 -> 2529.8665 | O28: kg/cm2 | Q28: fy | R28: =R3*1000/14.23 -> 2529.8665 | S28: kg/cm2 | U28: cf2 | V28: =0.38*V26 -> 10.948243 | Y28: cf2 | Z28: =0.38*Z26 -> 10.948243
E29: Lp | F29: =1.76*F27*F31 -> 84.185658 | G29: cm | I29: Lp | J29: =1.76*J27*J31 -> 84.185658 | K29: cm | M29: Lp | N29: =1.76*N27*N31 -> 84.185658 | O29: cm | Q29: Lp | R29: =1.76*R27*R31 -> 84.185658 | S29: cm | U29: cw1 | V29: =2.45*V26 -> 70.587359 | Y29: cw1 | Z29: =2.45*Z26 -> 70.587359
E30: Imin | F30: =3.125*($B$11+$B$12)*F7*10*(F5*100)^3 /2100000 -> 1258.5928 | G30: cm4 | I30: Imin | J30: =3.125*($B$11+$B$12)*J7*10*(J5*100)^3 /2100000 -> 1287.1972 | K30: cm4 | M30: Imin | N30: =3.125*($B$11+$B$12)*N7*10*(N5*100)^3 /2100000 -> 983.41898 | O30: cm4 | Q30: Imin | R30: =3.125*($B$11+$B$12)*R7*10*(R5*100)^3 /2100000 -> 1005.7694 | S30: cm4 | U30: cw2 | V30: =3.76*V26 -> 108.32999 | Y30: cw2 | Z30: =3.76*Z26 -> 108.32999
E31: Cte | F31: =+(2100000/F28)^0.5 -> 28.811167 | I31: Cte | J31: =+(2100000/J28)^0.5 -> 28.811167 | M31: Cte | N31: =+(2100000/N28)^0.5 -> 28.811167 | Q31: Cte | R31: =+(2100000/R28)^0.5 -> 28.811167 | U31: Stabla | V31: =+V8*100000/0.9/V24/0.75 -> 268.73069 | W31: cm3 | Y31: Stabla | Z31: =+Z8*100000/0.9/Z24/0.75 -> 843.02379 | AA31: cm3
E32: cf1 | F32: =0.3*F31 -> 8.64335 | I32: cf1 | J32: =0.3*J31 -> 8.64335 | M32: cf1 | N32: =0.3*N31 -> 8.64335 | Q32: cf1 | R32: =0.3*R31 -> 8.64335 | U32: IPN | V32: 240 | Y32: IPN | Z32: 400
E33: cf2 | F33: =0.38*F31 -> 10.948243 | I33: cf2 | J33: =0.38*J31 -> 10.948243 | M33: cf2 | N33: =0.38*N31 -> 10.948243 | Q33: cf2 | R33: =0.38*R31 -> 10.948243 | U33: Peso | V33: 36.2 | W33: kg/m | Y33: Peso | Z33: 92.6 | AA33: kg/m
E34: cw1 | F34: =2.45*F31 -> 70.587359 | I34: cw1 | J34: =2.45*J31 -> 70.587359 | M34: cw1 | N34: =2.45*N31 -> 70.587359 | Q34: cw1 | R34: =2.45*R31 -> 70.587359 | U34: Cortante | Y34: Cortante
E35: cw2 | F35: =3.76*F31 -> 108.32999 | I35: cw2 | J35: =3.76*J31 -> 108.32999 | M35: cw2 | N35: =3.76*N31 -> 108.32999 | Q35: cw2 | R35: =3.76*R31 -> 108.32999 | U35: Vug | V35: =+(V5*V6+V19/1000*V4*1.2)/2 -> 5.2652137 | W35: t | Y35: Vug | Z35: =+(Z5*Z6+Z19/1000*Z4*1.2)/2 -> 10.830281 | AA35: t
E36: Stabla | F36: =+F11*100000/0.9/F28 -> 135.91314 | G36: cm3 | I36: Stabla | J36: =+J11*100000/0.9/J28 -> 138.9642 | K36: cm3 | M36: Stabla | N36: =+N11*100000/0.9/N28 -> 115.30028 | O36: cm3 | Q36: Stabla | R36: =+R11*100000/0.9/R28 -> 117.8886 | S36: cm3 | U36: Vum | V36: =2*V45/(V4-'COL MET'!F7/100-V16/50) -> 6.5177011 | W36: t | Y36: Vum | Z36: =2*Z45/(Z4-'COL MET'!F7/100-Z16/50) -> 9.164863 | AA36: t
U37: Vu | V37: =+IF(V7="EMP",V35+V36,V35) -> 11.782915 | W37: t | Y37: Vu | Z37: =+IF(Z7="EMP",Z35+Z36,Z35) -> 19.995144 | AA37: t
E38: IPN | F38: 200 | I38: IPN | J38: 200 | M38: IPN | N38: 200 | Q38: IPN | R38: 200 | U38: Vn | V38: =+(V16-2*V15)*V17*V24/1000*0.6*V44 -> 15.5435 | W38: t | Y38: Vn | Z38: =+(Z16-2*Z15)*Z17*Z24/1000*0.6*Z44 -> 30.965566 | AA38: t
E39: Peso | F39: 26.3 | G39: kg/m | I39: Peso | J39: 26.3 | K39: kg/m | M39: Peso | N39: 26.3 | O39: kg/m | Q39: Peso | R39: 26.3 | S39: kg/m
U41: h/tw | V41: =+V16/V17 -> 67.5 | Y41: h/tw | Z41: =+Z16/Z17 -> 60
...

Sheet COL MET
A1: Datos Arq | E1: Calculos
A2: L1 | B2: =+'losa horm'!B2 -> 3.96 | C2: m | E2: At | F2: =+'COL horm'!F2 -> 23.4549 | G2: m2 | I2: Atiezadores
A3: L2 | B3: =+'losa horm'!B3 -> 6.75 | C3: m | E3: Pu | F3: =+F2*B13*B6/0.85 -> 49.166989 | G3: t | I3: Sentido b
A4: L3 | B4: =+'losa horm'!B4 -> 4.56 | C4: m | E4: Pres | F4: =+MIN(F22:F23) -> 202.10199 | G4: t | I4: Num | K4: u
A5: L4 | B5: =+'losa horm'!B5 -> 4.2 | C5: m | E5: D/C | F5: =+F3/F4 -> 0.24327811 | I5: l | K5: cm
A6: Pisos | B6: =+'losa horm'!B6 -> 2 | C6: u | E6: Datos de col | I6: e | K6: cm
A7: He | B7: =+'losa horm'!B7 -> 3.4 | C7: m | E7: b | F7: 24 | G7: =+IF(F7/F9/(J4+1)<B35,A35,IF(F7/F9/(J4+1)<B36,A36,"NCOMP")) -> COMP | I7: Ia | J7: =+J6*J5^3 /12 -> 0 | K7: cm4
B8: =+'VIGAS horm'!B8 -> Vivienda | E8: h | F8: 24 | G8: =+IF(F8/F9/(J11+1)<B35,A35,IF(F8/F9/(J11+1)<B36,A36,"NCOMP")) -> COMP | I8: Imin | J8: =18.4*$F$9^4 -> 1.15 | K8: cm4
E9: e | F9: 0.5 | G9: cm | I9: =+IF(J7>J8,"OK","NO") -> NO
E10: As | F10: =+F7*F8-(F7-2*F9)*(F8-2*F9)+J5*J6*2*J4*2+J12*J13*2*J11*2 -> 47 | G10: cm2 | I10: Sentido h | P10: https://www.youtube.com/@EdisonChavez-Ingenieria/videos
A11: =+'losa horm'!A12 -> Cm | B11: =+'VIGAS MET'!B11 -> 0.47575 | C11: =+'losa horm'!C12 -> t/m2 | E11: Peso | F11: =+F10*0.785 -> 36.895 | G11: kg/m | I11: Num | K11: u
A12: Cv | B12: =+'VIGAS horm'!B12 -> 0.2 | C12: t/m2 | E12: Ix | F12: =+F7*F8^3 /12-(F7-2*F9)*(F8-2*F9)^3 /12 -> 4327.9167 | G12: cm4 | I12: l | K12: cm | M12: =476-240 -> 236
A13: Cu | B13: =+B11*1.2+B12*1.6 -> 0.8909 | C13: t/m2 | E13: Iy | F13: =+F8*F7^3 /12-(F8-2*F9)*(F7-2*F9)^3 /12 -> 4327.9167 | G13: cm4 | I13: e | K13: cm
E14: Zx | F14: =+F9*F8^2 /2+F9*(F7-2*F9)*(F8-F9) -> 414.25 | G14: cm3 | I14: Ia | J14: =+J13*J12^3 /12 -> 0 | K14: cm4
A15: A | B15: 50 | C15: ksi | E15: Zy | F15: =+F9*F7^2 /2+(F8-2*F9)*(F7-F9)*F9 -> 414.25 | G15: cm3 | I15: Imin | J15: =18.4*$F$9^4 -> 1.15 | K15: cm4
A16: fy | B16: =+IF(I19="SI",B22,B20) -> 5522.7779 | C16: kg/cm2 | E16: rx | F16: =+(F12/F10)^0.5 -> 9.5960061 | G16: cm | I16: =+IF(J14>J15,"OK","NO") -> NO
A17: E | B17: =+IF(I19="SI",B23,B21) -> 2922049.6 | C17: kg/cm2 | E17: ry | F17: =+(F13/F10)^0.5 -> 9.5960061 | G17: cm | I17: RELLENO DE HORMIGON
A18: cte | B18: =+(B17/B16)^0.5 -> 23.001968 | E18: esbx | F18: =1.2*B7*100/F16 -> 42.517689 | G18: =+IF(F18<200,"OK","NO") -> OK
E19: esby | F19: =1.2*B7*100/F17 -> 42.517689 | G19: =+IF(F19<200,"OK","NO") -> OK | I19: SI
A20: fy | B20: =B15*1000/14.23 -> 3513.7034 | C20: kg/cm2 | E20: fex | F20: =3.1416^2*$B$17/F18^2 -> 15953.283 | G20: kg/cm2
A21: E | B21: 2100000 | C21: kg/cm2 | E21: fey | F21: =3.1416^2*$B$17/F19^2 -> 15953.283 | G21: kg/cm2 | I21: Condiciones
A22: fym | B22: =+B20+0.85*J23*J25/F10 -> 5522.7779 | C22: kg/cm2 | E22: Pres x | F22: =+IF(F18<4.71*$B$18,0.658^($B$16/F20)*$B$16*0.9*$F$10,0.877*F20*0.9*$F$10)/1000 -> 202.10199 | G22: t | I22: As | J22: =+F10/F7/F8 -> 0.081597222 | K22: =+IF(J22>4%,"OK","NO") -> OK
A23: Em | B23: =+B21+0.4*J26*J25/F10 -> 2922049.6 | C23: kg/cm2 | E23: Pres y | F23: =+IF(F19<4.71*$B$18,0.658^($B$16/F21)*$B$16*0.9*$F$10,0.877*F21*0.9*$F$10)/1000 -> 202.10199 | G23: t | I23: fc | J23: 210 | K23: =+IF(J23>=210,"OK","NO") -> OK
A24: Coef Ec | B24: 12600 | I24: emin | J24: =ROUNDDOWN(MAX(F7:F8)*(B20/3/B21)^0.5,1) -> 0.5 | K24: =+IF(F9>=J24,"OK","NO") -> OK
I25: Accon | J25: =+F7*F8-F10 -> 529 | K25: cm2
A26: Ca | B26: =F3*1000/0.9/F10/B20 -> 0.33080201 | E26: CF - VD | I26: Ec | J26: =+B24*J23^0.5 -> 182591.35 | K26: kg/cm2
A27: cte | B27: =+(B21/B20)^0.5 -> 24.447086 | E27: ∑Mcol | F27: =+F15*(2*B16-F3*1000/F10-(F3*1000-F3*1000/B6)/F10)/100000 -> 39.255973 | G27: =+F27/F28 -> 1.0639795
A28: Sin Hormigon | E28: ∑Mvig | F28: =+'VIGAS MET'!V45+'VIGAS MET'!Z45 -> 36.895423
A29: SISM | B29: =+IF(B26<0.125,2.45*B27*(1-0.93*B26),MAX(0.77*B27*(2.93-B26),1.49*B27)) -> 48.927968
A30: COMP | B30: =+IF(B26<0.125,3.76*B27*(1-2.75*B26),MAX(1.12*B27*(2.33-B26),1.49*B27)) -> 54.739512
A31: Con Hormigon
A32: SISM | B32: =1.4*B27 -> 34.22592
A33: COMP | B33: =2.26*B27 -> 55.250414
A34: Definitivo
A35: SISM | B35: =+IF(I19="SI",B32,B29) -> 34.22592
A36: COMP | B36: =+IF(I19="SI",B33,B30) -> 55.250414

Sheet SISMICA
A1: DATOS SIIMICOS | E1: Calculos Met | J1: Calculos Horm | O1: T | P1: Sa | Q1: Saine
A2: I | B2: 1 | E2: Tc | F2: =0.55*B11*B10/B9 -> 0.69813333 | G2: s | J2: Tc | K2: =+F2 -> 0.69813333 | L2: s | O2: 0 | P2: =+IF(O2<$F$2,$B$7*$B$8*$B$9,$B$7*$B$8*$B$9*($F$2/O2)^$B$12) -> 1.1904 | Q2: =+$B$2*P2/$B$3/$B$4/$B$5 -> 0.22044444 | U2: x | V2: y
A3: fi p | B3: 0.9 | E3: T f | F3: 0.45 | G3: s | J3: T f | K3: 0.48 | L3: s | O3: 0.1 | P3: =+IF(O3<$F$2,$B$7*$B$8*$B$9,$B$7*$B$8*$B$9*($F$2/O3)^$B$12) -> 1.1904 | Q3: =+$B$2*P3/$B$3/$B$4/$B$5 -> 0.22044444 | U3: =+F3 -> 0.45 | V3: 0
A4: fi e | B4: 1 | E4: Sa | F4: =VLOOKUP(F3,$O$2:$P$32,2,1) -> 1.1904 | J4: Sa | K4: =VLOOKUP(K3,$O$2:$P$32,2,1) -> 1.1904 | O4: 0.2 | P4: =+IF(O4<$F$2,$B$7*$B$8*$B$9,$B$7*$B$8*$B$9*($F$2/O4)^$B$12) -> 1.1904 | Q4: =+$B$2*P4/$B$3/$B$4/$B$5 -> 0.22044444 | U4: =+U3 -> 0.45 | V4: =+F4 -> 1.1904
A5: R | B5: 6 | E5: Coef | F5: =+B2*F4/B3/B4/B5 -> 0.22044444 | J5: Coef | K5: =+B2*K4/B3/B4/B5 -> 0.22044444 | O5: 0.3 | P5: =+IF(O5<$F$2,$B$7*$B$8*$B$9,$B$7*$B$8*$B$9*($F$2/O5)^$B$12) -> 1.1904 | Q5: =+$B$2*P5/$B$3/$B$4/$B$5 -> 0.22044444
O6: 0.4 | P6: =+IF(O6<$F$2,$B$7*$B$8*$B$9,$B$7*$B$8*$B$9*($F$2/O6)^$B$12) -> 1.1904 | Q6: =+$B$2*P6/$B$3/$B$4/$B$5 -> 0.22044444 | U6: 0 | V6: =+F4 -> 1.1904
A7: n | B7: 2.48 | O7: 0.5 | P7: =+IF(O7<$F$2,$B$7*$B$8*$B$9,$B$7*$B$8*$B$9*($F$2/O7)^$B$12) -> 1.1904 | Q7: =+$B$2*P7/$B$3/$B$4/$B$5 -> 0.22044444 | U7: =+U3 -> 0.45 | V7: =+F4 -> 1.1904
A8: Z | B8: 0.4 | O8: 0.6 | P8: =+IF(O8<$F$2,$B$7*$B$8*$B$9,$B$7*$B$8*$B$9*($F$2/O8)^$B$12) -> 1.1904 | Q8: =+$B$2*P8/$B$3/$B$4/$B$5 -> 0.22044444
A9: Fa | B9: 1.2 | O9: 0.7 | P9: =+IF(O9<$F$2,$B$7*$B$8*$B$9,$B$7*$B$8*$B$9*($F$2/O9)^$B$12) -> 1.1872256 | Q9: =+$B$2*P9/$B$3/$B$4/$B$5 -> 0.21985659
A10: Fd | B10: 1.19 | O10: 0.8 | P10: =+IF(O10<$F$2,$B$7*$B$8*$B$9,$B$7*$B$8*$B$9*($F$2/O10)^$B$12) -> 1.0388224 | Q10: =+$B$2*P10/$B$3/$B$4/$B$5 -> 0.19237452
A11: Fs | B11: 1.28 | O11: 0.9 | P11: =+IF(O11<$F$2,$B$7*$B$8*$B$9,$B$7*$B$8*$B$9*($F$2/O11)^$B$12) -> 0.92339769 | Q11: =+$B$2*P11/$B$3/$B$4/$B$5 -> 0.17099957
A12: r | B12: 1 | F12: elas | G12: inel | K12: elas | L12: inel | O12: 1 | P12: =+IF(O12<$F$2,$B$7*$B$8*$B$9,$B$7*$B$8*$B$9*($F$2/O12)^$B$12) -> 0.83105792 | Q12: =+$B$2*P12/$B$3/$B$4/$B$5 -> 0.15389961
E13: Deriva x | F13: 0.0026 | G13: =+F13*0.75*$B$5 -> 0.0117 | H13: =+IF(G13<2%,"OK","NO") -> OK | J13: Deriva x | K13: 0.0032 | L13: =+K13*0.75*$B$5 -> 0.0144 | M13: =+IF(L13<2%,"OK","NO") -> OK | O13: 1.1 | P13: =+IF(O13<$F$2,$B$7*$B$8*$B$9,$B$7*$B$8*$B$9*($F$2/O13)^$B$12) -> 0.7555072 | Q13: =+$B$2*P13/$B$3/$B$4/$B$5 -> 0.13990874
E14: Deriva Y | F14: 0.0022 | G14: =+F14*0.75*$B$5 -> 0.0099 | H14: =+IF(G14<2%,"OK","NO") -> OK | J14: Deriva Y | K14: 0.0025 | L14: =+K14*0.75*$B$5 -> 0.01125 | M14: =+IF(L14<2%,"OK","NO") -> OK | O14: 1.2 | P14: =+IF(O14<$F$2,$B$7*$B$8*$B$9,$B$7*$B$8*$B$9*($F$2/O14)^$B$12) -> 0.69254827 | Q14: =+$B$2*P14/$B$3/$B$4/$B$5 -> 0.12824968
O15: 1.3 | P15: =+IF(O15<$F$2,$B$7*$B$8*$B$9,$B$7*$B$8*$B$9*($F$2/O15)^$B$12) -> 0.63927532 | Q15: =+$B$2*P15/$B$3/$B$4/$B$5 -> 0.11838432
O16: 1.4 | P16: =+IF(O16<$F$2,$B$7*$B$8*$B$9,$B$7*$B$8*$B$9*($F$2/O16)^$B$12) -> 0.5936128 | Q16: =+$B$2*P16/$B$3/$B$4/$B$5 -> 0.1099283
O17: 1.5 | P17: =+IF(O17<$F$2,$B$7*$B$8*$B$9,$B$7*$B$8*$B$9*($F$2/O17)^$B$12) -> 0.55403861 | Q17: =+$B$2*P17/$B$3/$B$4/$B$5 -> 0.10259974
O18: 1.6 | P18: =+IF(O18<$F$2,$B$7*$B$8*$B$9,$B$7*$B$8*$B$9*($F$2/O18)^$B$12) -> 0.5194112 | Q18: =+$B$2*P18/$B$3/$B$4/$B$5 -> 0.096187259
O19: 1.7 | P19: =+IF(O19<$F$2,$B$7*$B$8*$B$9,$B$7*$B$8*$B$9*($F$2/O19)^$B$12) -> 0.4888576 | Q19: =+$B$2*P19/$B$3/$B$4/$B$5 -> 0.090529185
O20: 1.8 | P20: =+IF(O20<$F$2,$B$7*$B$8*$B$9,$B$7*$B$8*$B$9*($F$2/O20)^$B$12) -> 0.46169884 | Q20: =+$B$2*P20/$B$3/$B$4/$B$5 -> 0.085499786
O21: 1.9 | P21: =+IF(O21<$F$2,$B$7*$B$8*$B$9,$B$7*$B$8*$B$9*($F$2/O21)^$B$12) -> 0.43739891 | Q21: =+$B$2*P21/$B$3/$B$4/$B$5 -> 0.080999797
O22: 2 | P22: =+IF(O22<$F$2,$B$7*$B$8*$B$9,$B$7*$B$8*$B$9*($F$2/O22)^$B$12) -> 0.41552896 | Q22: =+$B$2*P22/$B$3/$B$4/$B$5 -> 0.076949807
O23: 2.1 | P23: =+IF(O23<$F$2,$B$7*$B$8*$B$9,$B$7*$B$8*$B$9*($F$2/O23)^$B$12) -> 0.39574187 | Q23: =+$B$2*P23/$B$3/$B$4/$B$5 -> 0.073285531
O24: 2.2 | P24: =+IF(O24<$F$2,$B$7*$B$8*$B$9,$B$7*$B$8*$B$9*($F$2/O24)^$B$12) -> 0.3777536 | Q24: =+$B$2*P24/$B$3/$B$4/$B$5 -> 0.06995437
O25: 2.3 | P25: =+IF(O25<$F$2,$B$7*$B$8*$B$9,$B$7*$B$8*$B$9*($F$2/O25)^$B$12) -> 0.36132953 | Q25: =+$B$2*P25/$B$3/$B$4/$B$5 -> 0.066912876
O26: 2.4 | P26: =+IF(O26<$F$2,$B$7*$B$8*$B$9,$B$7*$B$8*$B$9*($F$2/O26)^$B$12) -> 0.34627413 | Q26: =+$B$2*P26/$B$3/$B$4/$B$5 -> 0.06412484
... O32: 3 | P32: =+IF(O32<$F$2,$B$7*$B$8*$B$9,$B$7*$B$8*$B$9*($F$2/O32)^$B$12) -> 0.27701931 | Q32: =+$B$2*P32/$B$3/$B$4/$B$5 -> 0.051299872

Sheet Hoja3

Sheet Hoja1
B4: 1 | C4: DSR | D4: ETABS
B5: 2 | C5: CIMENT | D5: SAFE
B6: 3 | C6: MET | D6: ETABS | F6: 593 991139483
B7: 4 | C7: CONEX
B8: 5 | C8: REF EST
B9: 6 | C9: ANL
B10: 7 | C10: EST ESP
B11: 8 | C11: PUENT M1
B12: 9 | C12: PUNET M2
B13: 10 | C13: PUENT ESP
B14: 11 | C14: EDI DIS SIM
B15: 12 | C15: C 2P
B16: 13 | C16: PRESF

Sheet CIM
I1: qa | J1: 20 | K1: t/m2 | M1: rec | N1: 5 | O1: cm | Q1: Df | R1: 1.5 | S1: m
I2: bcol | J2: 30 | K2: cm | M2: fc | N2: 210 | O2: kg/cm2
A5: Label | B5: Unique Name | C5: FZ | D5: MX | E5: MY | H5: Ps | I5: Ms | J5: Area | K5: L | L5: Tipo
A6: 1 | B6: 3 | C6: 42.2454 | D6: -0.8601 | E6: -10.7925 | F6: =+ABS(D6) -> 0.8601 | G6: =+ABS(E6) -> 10.7925 | H6: =+MAX(C6:C7) -> 45.3617 | I6: =+MAX(F6:G7) -> 11.0767 | J6: =+H6*1.45/$J$1 -> 3.2887232 | K6: =+J6^0.5 -> 1.8134837 | L6: =+IF(K6<$K$32,$J$32,IF(K6<$K$33,$J$33,IF(K6<$K$34,$J$34,$J$35))) -> P4
A7: 1 | B7: 3 | C7: 45.3617 | D7: 11.0767 | E7: 1.7342 | F7: =+ABS(D7) -> 11.0767 | G7: =+ABS(E7) -> 1.7342
A8: 2 | B8: 6 | C8: 33.6532 | D8: 0.3448 | E8: -11.0991 | F8: =+ABS(D8) -> 0.3448 | G8: =+ABS(E8) -> 11.0991 | H8: =+MAX(C8:C9) -> 33.6532 | I8: =+MAX(F8:G9) -> 12.4468 | J8: =+H8*1.45/$J$1 -> 2.439857 | K8: =+J8^0.5 -> 1.5620042 | L8: P4 | AD8: =2.1*0.6 -> 1.26
A9: 2 | B9: 6 | C9: 27.0041 | D9: 12.4468 | E9: 2.007 | F9: =+ABS(D9) -> 12.4468 | G9: =+ABS(E9) -> 2.007
A10: 3 | B10: 9 | C10: 30.9754 | D10: -1.2469 | E10: -13.5819 | F10: =+ABS(D10) -> 1.2469 | G10: =+ABS(E10) -> 13.5819 | H10: =+MAX(C10:C11) -> 34.5584 | I10: =+MAX(F10:G11) -> 13.5819 | J10: =+H10*1.45/$J$1 -> 2.505484 | K10: =+J10^0.5 -> 1.5828721 | L10: P4
A11: 3 | B11: 9 | C11: 34.5584 | D11: 9.5215 | E11: -2.1359 | F11: =+ABS(D11) -> 9.5215 | G11: =+ABS(E11) -> 2.1359
A12: 4 | B12: 12 | C12: 24.4785 | D12: -0.8204 | E12: -12.899 | F12: =+ABS(D12) -> 0.8204 | G12: =+ABS(E12) -> 12.899 | H12: =+MAX(C12:C13) -> 24.4785 | I12: =+MAX(F12:G13) -> 12.899 | J12: =+H12*1.45/$J$1 -> 1.7746913 | K12: =+J12^0.5 -> 1.3321754 | L12: P4
A13: 4 | B13: 12 | C13: 20.5703 | D13: 10.3343 | E13: -1.0352 | F13: =+ABS(D13) -> 10.3343 | G13: =+ABS(E13) -> 1.0352
A14: 5 | B14: 26 | C14: 7.764 | D14: -0.2947 | E14: -2.046 | F14: =+ABS(D14) -> 0.2947 | G14: =+ABS(E14) -> 2.046 | H14: =+MAX(C14:C15) -> 13.8418 | I14: =+MAX(F14:G15) -> 2.046 | J14: =+H14*1.45/$J$1 -> 1.0035305 | K14: =+J14^0.5 -> 1.0017637 | L14: P2
A15: 5 | B15: 26 | C15: 13.8418 | D15: 1.9817 | E15: 0.2669 | F15: =+ABS(D15) -> 1.9817 | G15: =+ABS(E15) -> 0.2669
A16: 6 | B16: 27 | C16: 2.3953 | D16: 0.1476 | E16: -1.9684 | F16: =+ABS(D16) -> 0.1476 | G16: =+ABS(E16) -> 1.9684 | H16: =+MAX(C16:C17) -> 6.7295 | I16: =+MAX(F16:G17) -> 2.5838 | J16: =+H16*1.45/$J$1 -> 0.48788875 | K16: =+J16^0.5 -> 0.69849034 | L16: =+IF(K16<$K$32,$J$32,IF(K16<$K$33,$J$33,IF(K16<$K$34,$J$34,$J$35))) -> P1
A17: 6 | B17: 27 | C17: 6.7295 | D17: 2.5838 | E17: 0.3844 | F17: =+ABS(D17) -> 2.5838 | G17: =+ABS(E17) -> 0.3844
A18: 7 | B18: 19 | C18: 29.0324 | D18: 0.7557 | E18: -3.3965 | F18: =+ABS(D18) -> 0.7557 | G18: =+ABS(E18) -> 3.3965 | H18: =+MAX(C18:C19) -> 29.2005 | I18: =+MAX(F18:G19) -> 3.3965 | J18: =+H18*1.45/$J$1 -> 2.1170362 | K18: =+J18^0.5 -> 1.4550039 | L18: P3
A19: 7 | B19: 19 | C19: 29.2005 | D19: 2.9949 | E19: 0.5119 | F19: =+ABS(D19) -> 2.9949 | G19: =+ABS(E19) -> 0.5119
A20: 8 | B20: 22 | C20: 8.3102 | D20: 0.5137 | E20: -1.7421 | F20: =+ABS(D20) -> 0.5137 | G20: =+ABS(E20) -> 1.7421 | H20: =+MAX(C20:C21) -> 11.7349 | I20: =+MAX(F20:G21) -> 2.3147 | J20: =+H20*1.45/$J$1 -> 0.85078025 | K20: =+J20^0.5 -> 0.9223775 | L20: P2
A21: 8 | B21: 22 | C21: 11.7349 | D21: 2.3147 | E21: 0.0798 | F21: =+ABS(D21) -> 2.3147 | G21: =+ABS(E21) -> 0.0798
A22: 9 | B22: 25 | C22: 17.5339 | D22: 0.2828 | E22: -2.9355 | F22: =+ABS(D22) -> 0.2828 | G22: =+ABS(E22) -> 2.9355 | H22: =+MAX(C22:C23) -> 18.2902 | I22: =+MAX(F22:G23) -> 2.9355 | J22: =+H22*1.45/$J$1 -> 1.3260395 | K22: =+J22^0.5 -> 1.1515379 | L22: P2
A23: 9 | B23: 25 | C23: 18.2902 | D23: 1.8874 | E23: -1.334 | F23: =+ABS(D23) -> 1.8874 | G23: =+ABS(E23) -> 1.334
A24: 11 | B24: 33 | C24: 19.5435 | D24: 0.0842 | E24: -2.1908 | F24: =+ABS(D24) -> 0.0842 | G24: =+ABS(E24) -> 2.1908 | H24: =+MAX(C24:C25) -> 19.5435 | I24: =+MAX(F24:G25) -> 2.1908 | J24: =+H24*1.45/$J$1 -> 1.4169037 | K24: =+J24^0.5 -> 1.1903377 | L24: P2
A25: 11 | B25: 33 | C25: 16.7904 | D25: 1.6306 | E25: 0.2369 | F25: =+ABS(D25) -> 1.6306 | G25: =+ABS(E25) -> 0.2369
A26: 13 | B26: 39 | C26: 9.8424 | D26: -0.2068 | E26: -2.1094 | F26: =+ABS(D26) -> 0.2068 | G26: =+ABS(E26) -> 2.1094 | H26: =+MAX(C26:C27) -> 9.8424 | I26: =+MAX(F26:G27) -> 2.1094 | J26: =+H26*1.45/$J$1 -> 0.713574 | K26: =+J26^0.5 -> 0.84473309 | L26: =+IF(K26<$K$32,$J$32,IF(K26<$K$33,$J$33,IF(K26<$K$34,$J$34,$J$35))) -> P1
A27: 13 | B27: 39 | C27: 3.9336 | D27: 1.6802 | E27: -0.259 | F27: =+ABS(D27) -> 1.6802 | G27: =+ABS(E27) -> 0.259
A28: 16 | B28: 45 | C28: 13.5508 | D28: 0.2245 | E28: -0.9583 | F28: =+ABS(D28) -> 0.2245 | G28: =+ABS(E28) -> 0.9583 | H28: =+MAX(C28:C29) -> 13.5508 | I28: =+MAX(F28:G29) -> 2.3249 | J28: =+H28*1.45/$J$1 -> 0.982433 | K28: =+J28^0.5 -> 0.99117758 | L28: P2
A29: 16 | B29: 45 | C29: 11.3096 | D29: 2.3249 | E29: 0.9546 | F29: =+ABS(D29) -> 2.3249 | G29: =+ABS(E29) -> 0.9546
AA30: Exc | AB30: P. unit | AC30: Horm | AD30: P. unit | AE30: As | AF30: P. unit | AG30: Num | AH30: P final
K31: L | L31: vol | M31: Hp | N31: Pu | O31: Mu | P31: q1 | Q31: Mplint | R31: Asmin | S31: As cal | T31: As def | U31: fi | V31: sep | W31: Ld | X31: gancho | Y31: Patas | AA31: m3 | AB31: $/m3 | AC31: m3 | AD31: $/m3 | AE31: kg | AF31: $/kg
J32: P1 | K32: 1.2 | L32: =+(K32-$J$2/100)/2*100 -> 45 | M32: =MAX(ROUNDUP(L32/3+9,0)/100,0.25) -> 0.25 | N32: 15 | O32: 4.5 | P32: =+N32/K32^2+6*O32/K32^3 -> 26.041667 | Q32: =+P32*(L32/100)^2 /2 -> 2.6367187 | R32: =0.0018*100*M32*100 -> 4.5 | S32: =30*Q32/(M32*100-$N$1) -> 3.9550781 | T32: =+MAX(R32:S32) -> 4.5 | U32: 12 | V32: =0.785*U32^2 /T32 -> 25.12 | W32: =4200*0.098/(1.4*($N$2*0.098)^0.5)*U32/10 -> 77.768888 | X32: =15*U32/10 -> 18 | Y32: =+IF(W32<L32-$N$1,"NO","SI") -> SI | AA32: =+K32^2*$R$1*1.33 -> 2.8728 | AB32: 15 | AC32: =+K32^2*M32 -> 0.36 | AD32: 160 | AE32: =+(INT(K32/(V32/100))+1)*2*K32*0.00785*U32^2*0.785 -> 10.648368 | AF32: 2.4 | AG32: 2 | AH32: =+(AA32*AB32+AC32*AD32+AE32*AF32)*AG32 -> 252.49617
J33: P2 | K33: 1.5 | L33: =+(K33-$J$2/100)/2*100 -> 60 | M33: =ROUNDUP(L33/3+9,0)/100 -> 0.29 | N33: 30 | O33: 4.5 | P33: =+N33/K33^2+6*O33/K33^3 -> 21.333333 | Q33: =+P33*(L33/100)^2 /2 -> 3.84 | R33: =0.0018*100*M33*100 -> 5.22 | S33: =30*Q33/(M33*100-$N$1) -> 4.8 | T33: =+MAX(R33:S33) -> 5.22 | U33: =+U32 -> 12 | V33: =0.785*U33^2 /T33 -> 21.655172 | W33: =4200*0.098/(1.4*($N$2*0.098)^0.5)*U33/10 -> 77.768888 | X33: =15*U33/10 -> 18 | Y33: =+IF(W33<L33-$N$1,"NO","SI") -> SI | AA33: =+K33^2*$R$1*1.33 -> 4.48875 | AB33: =+AB32 -> 15 | AC33: =+K33^2*M33 -> 0.6525 | AD33: =+AD32 -> 160 | AE33: =+(INT(K33/(V33/100))+1)*2*K33*0.00785*U33^2*0.785 -> 18.634644 | AF33: =+AF32 -> 2.4 | AG33: 5 | AH33: =+(AA33*AB33+AC33*AD33+AE33*AF33)*AG33 -> 1082.272
J34: P3 | K34: 1.8 | L34: =+(K34-$J$2/100)/2*100 -> 75 | M34: =ROUNDUP(L34/3+9,0)/100 -> 0.34 | N34: 45 | O34: 6 | P34: =+N34/K34^2+6*O34/K34^3 -> 20.061728 | Q34: =+P34*(L34/100)^2 /2 -> 5.6423611 | R34: =0.0018*100*M34*100 -> 6.12 | S34: =30*Q34/(M34*100-$N$1) -> 5.8369253 | T34: =+MAX(R34:S34) -> 6.12 | U34: =+U33 -> 12 | V34: =0.785*U34^2 /T34 -> 18.470588 | W34: =4200*0.098/(1.4*($N$2*0.098)^0.5)*U34/10 -> 77.768888 | X34: =15*U34/10 -> 18 | Y34: =+IF(W34<L34-$N$1,"NO","SI") -> SI | AA34: =+K34^2*$R$1*1.33 -> 6.4638 | AB34: =+AB33 -> 15 | AC34: =+K34^2*M34 -> 1.1016 | AD34: =+AD33 -> 160 | AE34: =+(INT(K34/(V34/100))+1)*2*K34*0.00785*U34^2*0.785 -> 31.945104 | AF34: =+AF33 -> 2.4 | AG34: 1 | AH34: =+(AA34*AB34+AC34*AD34+AE34*AF34)*AG34 -> 349.88125
J35: P4 | K35: 2.1 | L35: =+(K35-$J$2/100)/2*100 -> 90 | M35: =ROUNDUP(L35/3+9,0)/100 -> 0.39 | N35: =46*1.5 -> 69 | O35: =14*1.5 -> 21 | P35: =+N35/K35^2+6*O35/K35^3 -> 29.251701 | Q35: =+P35*(L35/100)^2 /2 -> 11.846939 | R35: =0.0018*100*M35*100 -> 7.02 | S35: =30*Q35/(M35*100-$N$1) -> 10.453181 | T35: =+MAX(R35:S35) -> 10.453181 | U35: =+U34 -> 12 | V35: =0.785*U35^2 /T35 -> 10.813933 | W35: =4200*0.098/(1.4*($N$2*0.098)^0.5)*U35/10 -> 77.768888 | X35: =15*U35/10 -> 18 | Y35: =+IF(W35<L35-$N$1,"NO","SI") -> NO | AA35: =+K35^2*$R$1*1.33 -> 8.79795 | AB35: =+AB34 -> 15 | AC35: =+K35^2*M35 -> 1.7199 | AD35: =+AD34 -> 160 | AE35: =+(INT(K35/(V35/100))+1)*2*K35*0.00785*U35^2*0.785 -> 74.538576 | AF35: =+AF34 -> 2.4 | AG35: 4 | AH35: =+(AA35*AB35+AC35*AD35+AE35*AF35)*AG35 -> 2344.1833
AG36: total | AH36: =SUBTOTAL(9,AH32:AH35) -> 4028.8327
AG37: Area | AH37: =10.7*9.6 -> 102.72
H38: Ps | I38: 46 | J38: t | AG38: P/m2 | AH38: =+AH36/AH37 -> 39.221502
H39: Ms | I39: 12 | J39: t-m
H40: Acim | I40: =+I38*1.45/J1 -> 3.335 | J40: m2
H41: L | I41: 2.1 | J41: m2
H42: q1 | I42: =+I38/I41^2+6*I39/I41^3 -> 18.205377 | J42: =+IF(I42>J1,"NO","OK") -> OK

Sheet DATOS MEMORIA
G3: VIGA A FLEXION
A4: AREAS EN PLANTA | G4: L1 | H4: 6 | I4: m | K4: AREAS EN PLANTA BLOQUE 2
A5: UBICACION | B5: U | C5: AREA | D5: CANTIDAD | E5: TOTAL | G5: Lt1 | H5: 3.55 | I5: m | K5: UBICACION | L5: U | M5: AREA | N5: CANTIDAD | O5: TOTAL
A6: LOSA N +3.50 | B6: m2 | C6: 113.4 | D6: 1 | E6: =+C6*D6 -> 113.4 | G6: Lt2 | H6: 3.55 | I6: m | K6: LOSA N +0,00 | L6: m2 | M6: 864 | N6: 1 | O6: =+M6*N6 -> 864
A7: LOSA N +6.50 | B7: m2 | C7: 113.4 | D7: 1 | E7: =+C7*D7 -> 113.4 | G7: At | H7: =+(H4+(H4-H5))/2*H5/2+(H4+(H4-H6))/2*H6/2 -> 14.99875 | I7: m2 | K7: LOSA N +3.50 | L7: m2 | M7: 864 | N7: 1 | O7: =+M7*N7 -> 864
C8: Área Total | E8: =SUM(E6:E7) -> 226.8 | G8: Cu | H8: 985 | I8: kg/m2 | K8: LOSA N +7.00 | L8: m2 | M8: 864 | N8: 1 | O8: =+M8*N8 -> 864
G9: Wu | H9: =+H7*H8 -> 14773.769 | I9: kg | K9: LOSA N +10.50 | L9: m2 | M9: 864 | N9: 1 | O9: =+M9*N9 -> 864
A10: PESO DE MAMPOSTERIAS | G10: Wr | H10: =+H9/H4 -> 2462.2948 | I10: kg/m | K10: LOSA N +14.00 | M10: 864 | N10: 1 | O10: =+M10*N10 -> 864
A11: Área de edificación | C11: =+E8 -> 226.8 | D11: m2 | G11: Mult | H11: =+H10*H4*H4/10*100 -> 886426.12 | I11: kg-cm | M11: Área Total | O11: =SUM(O6:O10) -> 4320
A12: factor de incidencia | C12: 1.7 | D12: m2/m2 | G12: d | H12: =+(H11/0.145/210/35)^0.5 -> 28.83989 | I12: cm
A13: Espesor de mampostería | C13: 0.13 | D13: m | K13: BLOQUE 2
A14: Volumen de mampostería | C14: =+C11*C12*C13 -> 50.1228 | D14: m3 | K14: PESO DE MAMPOSTERIAS
A15: Peso volumétrico | C15: 750 | D15: kg/m3 | K15: Área de edificación | M15: =+O11 -> 4320 | N15: m2
A16: Peso total de mampostería | C16: =+C15*C14 -> 37592.1 | D16: kg | K16: factor de incidencia | M16: 1.7 | N16: m2/m2
A17: Peso de Mampostería | C17: =+C16/C11 -> 165.75 | D17: kg/m2 | K17: Espesor de mampostería | M17: 0.13 | N17: m
K18: Volumen de mampostería | M18: =+M15*M16*M17 -> 954.72 | N18: m3
K19: Peso volumétrico | M19: 850 | N19: kg/m3
A20: CARGA MUERTA | K20: Peso total de mampostería | M20: =+M18*M19 -> 811512 | N20: kg
A21: Peso propio losa 10 cm | C21: 240 | D21: kg/m2 | K21: Peso de Mampostería | M21: =+M20/M15 -> 187.85 | N21: kg/m2
A22: Mamposterías | C22: =+C17 -> 165.75 | D22: kg/m2
A23: Recubrimientos | C23: 40 | D23: kg/m2
A24: Instalaciones | C24: 30 | D24: kg/m2 | K24: CARGA MUERTA
A25: TOTAL | C25: =SUM(C21:C24) -> 475.75 | D25: kg/m2 | K25: Peso de loseta de 10 cm | M25: 240 | N25: kg/m2
K26: Mamposterías | M26: =+M21 -> 187.85 | N26: kg/m2
K27: Recubrimientos | M27: 53 | N27: kg/m2
K28: Instalaciones | M28: 20 | N28: kg/m2
K29: TOTAL | M29: =SUM(M25:M28) -> 500.85 | N29: kg/m2

Sheet DATOS SISMICOS
A2: COEFICIENTES PARA ESPECTRO DE RESPUESTAS | D2: T | E2: Sa | F2: Sa ine
A3: Zona sísmica | B3: V | C3: Tabla 1 | D3: 0 | E3: =+IF(D3<$B$11,$B$9*$B$4*$B$6,$B$9*$B$4*$B$6*($B$11/D3)^$B$10) -> 1.1904 | F3: =+$B$18*E3/$B$16/$B$17/$B$15 -> 0.22044444
A4: Valor Factor Z | B4: 0.4 | C4: Tabla 1 | D4: 0.1 | E4: =+IF(D4<$B$11,$B$9*$B$4*$B$6,$B$9*$B$4*$B$6*($B$11/D4)^$B$10) -> 1.1904 | F4: =+$B$18*E4/$B$16/$B$17/$B$15 -> 0.22044444
A5: Tipo de suelo | B5: D | C5: Estudio | D5: 0.2 | E5: =+IF(D5<$B$11,$B$9*$B$4*$B$6,$B$9*$B$4*$B$6*($B$11/D5)^$B$10) -> 1.1904 | F5: =+$B$18*E5/$B$16/$B$17/$B$15 -> 0.22044444
A6: Coeficiente de ampliación de suelo en la zona de periodo corto Fa | B6: 1.2 | C6: Tabla 3 | D6: 0.3 | E6: =+IF(D6<$B$11,$B$9*$B$4*$B$6,$B$9*$B$4*$B$6*($B$11/D6)^$B$10) -> 1.1904 | F6: =+$B$18*E6/$B$16/$B$17/$B$15 -> 0.22044444
A7: Ampliación de las ordenadas del espectro elástico de respuesta de desplazamiento para diseño en roca Fd | B7: 1.19 | C7: Tabla 4 | D7: 0.4 | E7: =+IF(D7<$B$11,$B$9*$B$4*$B$6,$B$9*$B$4*$B$6*($B$11/D7)^$B$10) -> 1.1904 | F7: =+$B$18*E7/$B$16/$B$17/$B$15 -> 0.22044444
A8: Comportamiento no lineal de los suelos Fs | B8: 1.28 | C8: Tabla 5 | D8: 0.5 | E8: =+IF(D8<$B$11,$B$9*$B$4*$B$6,$B$9*$B$4*$B$6*($B$11/D8)^$B$10) -> 1.1904 | F8: =+$B$18*E8/$B$16/$B$17/$B$15 -> 0.22044444
A9: Relación de amplificación espectral ɳ | B9: 2.48 | C9: Sección 3,3,1 | D9: 0.6 | E9: =+IF(D9<$B$11,$B$9*$B$4*$B$6,$B$9*$B$4*$B$6*($B$11/D9)^$B$10) -> 1.1904 | F9: =+$B$18*E9/$B$16/$B$17/$B$15 -> 0.22044444
A10: Factor usado en el espectro de diseño elástico r | B10: 1 | C10: Sección 3,3,1 | D10: 0.7 | E10: =+IF(D10<$B$11,$B$9*$B$4*$B$6,$B$9*$B$4*$B$6*($B$11/D10)^$B$10) -> 1.1872256 | F10: =+$B$18*E10/$B$16/$B$17/$B$15 -> 0.21985659
A11: Periodo limite de vibración en el espectro elástico Tc | B11: =0.55*B8*B7/B6 -> 0.69813333 | C11: Sección 3,3,1 | D11: 0.8 | E11: =+IF(D11<$B$11,$B$9*$B$4*$B$6,$B$9*$B$4*$B$6*($B$11/D11)^$B$10) -> 1.0388224 | F11: =+$B$18*E11/$B$16/$B$17/$B$15 -> 0.19237452
D12: 0.9 | E12: =+IF(D12<$B$11,$B$9*$B$4*$B$6,$B$9*$B$4*$B$6*($B$11/D12)^$B$10) -> 0.92339769 | F12: =+$B$18*E12/$B$16/$B$17/$B$15 -> 0.17099957
D13: 1 | E13: =+IF(D13<$B$11,$B$9*$B$4*$B$6,$B$9*$B$4*$B$6*($B$11/D13)^$B$10) -> 0.83105792 | F13: =+$B$18*E13/$B$16/$B$17/$B$15 -> 0.15389961
A14: FACTORES PARA LA REDUCCION DEL ESPECTRO | D14: 1.1 | E14: =+IF(D14<$B$11,$B$9*$B$4*$B$6,$B$9*$B$4*$B$6*($B$11/D14)^$B$10) -> 0.7555072 | F14: =+$B$18*E14/$B$16/$B$17/$B$15 -> 0.13990874
A15: Factor de reducción de resistencia sísmica R | B15: 6 | C15: Sección 6,3,2 | D15: 1.2 | E15: =+IF(D15<$B$11,$B$9*$B$4*$B$6,$B$9*$B$4*$B$6*($B$11/D15)^$B$10) -> 0.69254827 | F15: =+$B$18*E15/$B$16/$B$17/$B$15 -> 0.12824968
A16: Coeficiente de configuración en planta ɸ p | B16: 0.9 | C16: Sección 6,3,2 | D16: 1.3 | E16: =+IF(D16<$B$11,$B$9*$B$4*$B$6,$B$9*$B$4*$B$6*($B$11/D16)^$B$10) -> 0.63927532 | F16: =+$B$18*E16/$B$16/$B$17/$B$15 -> 0.11838432
A17: Coeficiente de configuración en elevación ɸ e | B17: 1 | C17: Sección 6,3,2 | D17: 1.4 | E17: =+IF(D17<$B$11,$B$9*$B$4*$B$6,$B$9*$B$4*$B$6*($B$11/D17)^$B$10) -> 0.5936128 | F17: =+$B$18*E17/$B$16/$B$17/$B$15 -> 0.1099283
A18: Factor de Importancia de la estructura I | B18: 1 | C18: Tabla 6 | D18: 1.5 | E18: =+IF(D18<$B$11,$B$9*$B$4*$B$6,$B$9*$B$4*$B$6*($B$11/D18)^$B$10) -> 0.55403861 | F18: =+$B$18*E18/$B$16/$B$17/$B$15 -> 0.10259974
D19: 1.6 | E19: =+IF(D19<$B$11,$B$9*$B$4*$B$6,$B$9*$B$4*$B$6*($B$11/D19)^$B$10) -> 0.5194112 | F19: =+$B$18*E19/$B$16/$B$17/$B$15 -> 0.096187259
D20: 1.7 | E20: =+IF(D20<$B$11,$B$9*$B$4*$B$6,$B$9*$B$4*$B$6*($B$11/D20)^$B$10) -> 0.4888576 | F20: =+$B$18*E20/$B$16/$B$17/$B$15 -> 0.090529185
A21: PERIODO DE VIBRACION METODO 1 | D21: 1.8 | E21: =+IF(D21<$B$11,$B$9*$B$4*$B$6,$B$9*$B$4*$B$6*($B$11/D21)^$B$10) -> 0.46169884 | F21: =+$B$18*E21/$B$16/$B$17/$B$15 -> 0.085499786
A22: Coeficiente que depende del tipo de edificio | B22: 0.072 | C22: Sección 6,3,3 | D22: 1.9 | E22: =+IF(D22<$B$11,$B$9*$B$4*$B$6,$B$9*$B$4*$B$6*($B$11/D22)^$B$10) -> 0.43739891 | F22: =+$B$18*E22/$B$16/$B$17/$B$15 -> 0.080999797
A23: Altura del edificio | B23: 6.55 | C23: Planos | D23: 2 | E23: =+IF(D23<$B$11,$B$9*$B$4*$B$6,$B$9*$B$4*$B$6*($B$11/D23)^$B$10) -> 0.41552896 | F23: =+$B$18*E23/$B$16/$B$17/$B$15 -> 0.076949807
A24: Factor α | B24: 0.8 | C24: Sección 6,3,3 | D24: 2.1 | E24: =+IF(D24<$B$11,$B$9*$B$4*$B$6,$B$9*$B$4*$B$6*($B$11/D24)^$B$10) -> 0.39574187 | F24: =+$B$18*E24/$B$16/$B$17/$B$15 -> 0.073285531
A25: T Periodo de vibración | B25: =+B22*B23^B24 -> 0.32383631 | C25: Formula | D25: 2.2 | E25: =+IF(D25<$B$11,$B$9*$B$4*$B$6,$B$9*$B$4*$B$6*($B$11/D25)^$B$10) -> 0.3777536 | F25: =+$B$18*E25/$B$16/$B$17/$B$15 -> 0.06995437
A26: Aceleración Inelástica SA ine | B26: =VLOOKUP(B25,D3:E33,2,1)*B18/B16/B17/B15 -> 0.22044444 | C26: Cuadro | D26: 2.3 | E26: =+IF(D26<$B$11,$B$9*$B$4*$B$6,$B$9*$B$4*$B$6*($B$11/D26)^$B$10) -> 0.36132953 | F26: =+$B$18*E26/$B$16/$B$17/$B$15 -> 0.066912876
A27: Valor k | B27: =+IF(B25<0.5,1,IF(B25>2.5,2,0.75+0.5*B25)) -> 1 | C27: Seccion 6,3,5 | D27: 2.4 | E27: =+IF(D27<$B$11,$B$9*$B$4*$B$6,$B$9*$B$4*$B$6*($B$11/D27)^$B$10) -> 0.34627413 | F27: =+$B$18*E27/$B$16/$B$17/$B$15 -> 0.06412484
D28: 2.5 | E28: =+IF(D28<$B$11,$B$9*$B$4*$B$6,$B$9*$B$4*$B$6*($B$11/D28)^$B$10) -> 0.33242317 | F28: =+$B$18*E28/$B$16/$B$17/$B$15 -> 0.061559846
D29: 2.6 | E29: =+IF(D29<$B$11,$B$9*$B$4*$B$6,$B$9*$B$4*$B$6*($B$11/D29)^$B$10) -> 0.31963766 | F29: =+$B$18*E29/$B$16/$B$17/$B$15 -> 0.05919216
D30: 2.7 | E30: =+IF(D30<$B$11,$B$9*$B$4*$B$6,$B$9*$B$4*$B$6*($B$11/D30)^$B$10) -> 0.30779923 | F30: =+$B$18*E30/$B$16/$B$17/$B$15 -> 0.056999857
D31: 2.8 | E31: =+IF(D31<$B$11,$B$9*$B$4*$B$6,$B$9*$B$4*$B$6*($B$11/D31)^$B$10) -> 0.2968064 | F31: =+$B$18*E31/$B$16/$B$17/$B$15 -> 0.054964148
D32: 2.9 | E32: =+IF(D32<$B$11,$B$9*$B$4*$B$6,$B$9*$B$4*$B$6*($B$11/D32)^$B$10) -> 0.2865717 | F32: =+$B$18*E32/$B$16/$B$17/$B$15 -> 0.053068833
D33: 3 | E33: =+IF(D33<$B$11,$B$9*$B$4*$B$6,$B$9*$B$4*$B$6*($B$11/D33)^$B$10) -> 0.27701931 | F33: =+$B$18*E33/$B$16/$B$17/$B$15 -> 0.051299872
E37: =2.48*0.4*1.2*(0.7/0.727) -> 1.1461898
E38: =1.146/6 -> 0.191
D42: =145000*2.3 -> 333500 | G42: =0.004445*0.75*6 -> 0.0200025

Sheet Hoja4
A4: TABLE: Modal Participating Mass Ratios
A5: Case | B5: Mode | C5: Period | D5: UX | E5: UY | F5: UZ | G5: SumUX | H5: SumUY | I5: SumUZ | J5: RX | K5: RY | L5: RZ | M5: SumRX | N5: SumRY | O5: SumRZ
C6: sec
A7: Modal | B7: 1 | C7: 0.462 | D7: 0.8959 | E7: 0.0009 | F7: 0 | G7: 0.8959 | H7: 0.0009 | I7: 0 | J7: 0.0001 | K7: 0.1574 | L7: 0.007 | M7: 0.0001 | N7: 0.1574 | O7: 0.007 | P7: =SUM(J7:L7) -> 0.1645 | Q7: =+L7/P7 -> 0.042553191
A8: Modal | B8: 2 | C8: 0.417 | D8: 0.0022 | E8: 0.8717 | F8: 0 | G8: 0.8981 | H8: 0.8726 | I8: 0 | J8: 0.1344 | K8: 0.0004 | L8: 0.0446 | M8: 0.1345 | N8: 0.1579 | O8: 0.0516 | P8: =SUM(J8:L8) -> 0.1794 | Q8: =+L8/P8 -> 0.24860647
A9: Modal | B9: 3 | C9: 0.337 | D9: 0.0051 | E9: 0.045 | F9: 0 | G9: 0.9032 | H9: 0.9176 | I9: 0 | J9: 0.0063 | K9: 0.0009 | L9: 0.8652 | M9: 0.1408 | N9: 0.1588 | O9: 0.9168 | P9: =SUM(J9:L9) -> 0.8724 | Q9: =+L9/P9 -> 0.99174691
A10: Modal | B10: 4 | C10: 0.132 | D10: 0.0937 | E10: 0.0011 | F10: 0 | G10: 0.9969 | H10: 0.9187 | I10: 0 | J10: 0.0116 | K10: 0.8147 | L10: 0.0014 | M10: 0.1524 | N10: 0.9735 | O10: 0.9182
A11: Modal | B11: 5 | C11: 0.128 | D11: 0.0019 | E11: 0.0781 | F11: 0 | G11: 0.9988 | H11: 0.9968 | I11: 0 | J11: 0.813 | K11: 0.0164 | L11: 0.003 | M11: 0.9654 | N11: 0.9899 | O11: 0.9212
A12: Modal | B12: 6 | C12: 0.103 | D12: 0.0012 | E12: 0.0032 | F12: 0 | G12: 1 | H12: 1 | I12: 0 | J12: 0.0342 | K12: 0.01 | L12: 0.0788 | M12: 0.9997 | N12: 1 | O12: 1
A13: Modal | B13: 7 | C13: 0.025 | D13: 2.147e-06 | E13: 2.306e-05 | F13: 0 | G13: 1 | H13: 1 | I13: 0 | J13: 0.0001 | K13: 1.144e-05 | L13: 7.917e-06 | M13: 0.9998 | N13: 1 | O13: 1
A14: Modal | B14: 8 | C14: 0.024 | D14: 7.699e-07 | E14: 6.459e-06 | F14: 0 | G14: 1 | H14: 1 | I14: 0 | J14: 0.0002 | K14: 1.459e-05 | L14: 1.715e-06 | M14: 1 | N14: 1 | O14: 1
A15: Modal | B15: 9 | C15: 0.023 | D15: 6.382e-07 | E15: 0 | F15: 0 | G15: 1 | H15: 1 | I15: 0 | J15: 0 | K15: 3.351e-06 | L15: 0 | M15: 1 | N15: 1 | O15: 1
A16: Modal | B16: 10 | C16: 0.022 | D16: 0 | E16: 0 | F16: 0 | G16: 1 | H16: 1 | I16: 0 | J16: 0 | K16: 3.672e-06 | L16: 0 | M16: 1 | N16: 1 | O16: 1
A17: Modal | B17: 11 | C17: 0.015 | D17: 0 | E17: 7.568e-07 | F17: 0 | G17: 1 | H17: 1 | I17: 0 | J17: 5.508e-06 | K17: 0 | L17: 0 | M17: 1 | N17: 1 | O17: 1
A18: Modal | B18: 12 | C18: 0.015 | D18: 0 | E18: 0 | F18: 0 | G18: 1 | H18: 1 | I18: 0 | J18: 2.768e-06 | K18: 0 | L18: 0 | M18: 1 | N18: 1 | O18: 1
E21: Distorison SISMO X
E22: x1 | F22: 0.85 | G22: cm
E23: x2 | F23: 0.78 | G23: cm
E24: V prom | F24: =+(F22+F23)/2 -> 0.815 | G24: cm
E25: Aum | F25: =+F24*1.2 -> 0.978 | G25: cm
E27: Val max | F27: =+MAX(F22:F23) -> 0.85 | G27: cm
E28: =+IF(F27<F25,"OK","NO") -> OK
